Workbook

Sheet Summary
A1: KnowledgeBridge — Cost Summary
A2: All figures are estimates from the Assumptions tab. Change blue cells there and everything updates.
A4: Item | B4: Value | C4: Note
A5: Provider / who pays | B5: =Assumptions!$B$6&" / "&Assumptions!$B$7 -> OpenAI / Sponsor | C5: Sponsor-provided API keys
A6: Synthesis model | B6: =Assumptions!$B$10 -> gpt-6-luna | C6: Synthesis run by gbrain (may change)
A7: Embedding model | B7: =Assumptions!$B$11 -> text-embedding-3-large | C7: gbrain default
A8: Cost per Synthesis query (cache miss) | B8: ='Unit Costs'!E6 -> 0.0007892 | C8: Medium tier
A9: Cost per Search query | B9: ='Unit Costs'!E5 -> 5.2e-06 | C9: Low tier: embedding only
A10: Dev-phase API budget (with buffer) | B10: ='Dev Phase Cost'!D14 -> 1.58163 | C10: Paid by sponsor
A11: Dev monthly cost ceiling (token budget) | B11: ='Dev Phase Cost'!D17 -> 2 | C11: Suggested OpenAI spend limit
A12: Total project cost | B12: ='Other Costs'!D18 -> 1.58163 | C12: API + $0 tooling; labor excluded
A13: Team out-of-pocket | B13: ='Other Costs'!D20 -> 0
A14: Projected monthly cost @ 50 users | B14: ='Production Projection'!B15 -> 1.1484975 | C14: Hypothetical, with buffer
A15: Projected monthly cost @ 75 users | B15: ='Production Projection'!C15 -> 1.723965 | C15: Hypothetical, with buffer
A16: Projected monthly cost @ 100 users | B16: ='Production Projection'!D15 -> 2.296995 | C16: Hypothetical, with buffer
A19: Tabs
A20: Assumptions | B20: Every input and where it came from
A21: Unit Costs | B21: Cost of one Search, Synthesis and ingestion
A22: Dev Phase Cost | B22: 12-week build/test spend
A23: Production Projection | B23: 50/75/100-user monthly estimate (not deployed)
A24: Model Comparison | B24: Same usage on Astra, Sol, Luna
A25: Other Costs | B25: Full cost list including $0 items
A26: Price Reference | B26: OpenAI unit prices with sources

Sheet Assumptions
A1: KnowledgeBridge — Cost Assumptions
A2: Blue = input you can change. Yellow = key assumption to confirm with the team. Black = formula. Green = pulled from another sheet.
A4: Assumption | B4: Value | C4: Unit | D4: Source / basis
A5: Provider & models
A6: LLM & embedding provider | B6: OpenAI | C6: text | D6: Team decision; sponsor-provided OpenAI keys (Plan 10.1, 16 Q11)
A7: Who pays API costs | B7: Sponsor | C7: text | D7: Sponsor provided OpenAI API keys; team out-of-pocket = $0
A8: Pricing tier | B8: Standard, short context | C8: text | D8: Live user requests (not Batch); requests are ~5K tokens, far below long-context threshold
A9: Synthesis performed by | B9: gbrain | C9: text | D9: Expected; may change after testing (Plan 16 Q4). If the backend calls OpenAI directly, revisit the token rows below
A10: Synthesis (chat) model | B10: gpt-6-luna | C10: model | D10: Pick from dropdown.
A11: Embedding model | B11: text-embedding-3-large | C11: model | D11: gbrain's OpenAI embedding default (gbrain docs).
A12: Characters per token | B12: 4 | C12: chars | D12: OpenAI rule of thumb (~4 chars ≈ 1 token, English); same value Plan 10.2 uses
A13: Development phase (12-week capstone)
A14: Project length | B14: 12 | C14: weeks | D14: Spec milestones; Plan 7
A15: Weeks making live API calls | B15: 7 | C15: weeks | D15: Weeks 6–12. Wk 1–3 design/setup; routine dev uses mock gbrain (Plan 12.2, 15.7)
A16: Team members generating API calls | B16: 5 | C16: people | D16: Five-person team (Plan 1, 5)
A17: Ad-hoc Synthesis queries per member per live week | B17: 40 | C17: queries | D17: Team estimate: manual testing + demo prep (~8 per build day)
A18: Ad-hoc Search queries per member per live week | B18: 60 | C18: queries | D18: Team estimate. Search = one embedding, no LLM (Spec 2)
A19: Synthesis cache hit rate (dev) | B19: 0.1 | C19: % | D19: Spec 2: exact-match cache has low hit rate; cache resets on every KB change (Plan 4.4)
A20: Evaluation questions | B20: 60 | C20: questions | D20: Plan 9.1: ~60-question ground-truth set
A21: Evaluation runs | B21: 3 | C21: runs | D21: Plan 7: baseline (wk 9), formal study (wk 10), re-run after fixes (wk 10)
A22: Test corpus size | B22: 50 | C22: Markdown docs | D22: Spec Milestone 1; Plan 8.2: 50 synthetic docs
A23: Average document length | B23: 12000 | C23: chars | D23: Placeholder ≈ 2,000 words. Measure: average character count of the 50 docs
A24: Full corpus ingestions during dev | B24: 6 | C24: times | D24: Team estimate: initial load, schema changes, bug fixes, demo resets
A25: LLM entity-extraction call per doc? (1=yes, 0=no) | B25: 0 | C25: flag | D25: Spec tech stack: gbrain uses zero-additional-LLM-call entity extraction
A26: Tokens per Synthesis call (assumes gbrain builds the prompt)
A27: User question length | B27: 40 | C27: tokens | D27: Team estimate (~30 words)
A28: System prompt (citations, AI label, gap rules) | B28: 600 | C28: tokens | D28: Placeholder. Measure once gbrain's synthesis prompt is known
A29: Retrieved chunks sent to LLM | B29: 6 | C29: chunks | D29: Placeholder. gbrain retrieval setting (top-k)
A30: Tokens per chunk | B30: 700 | C30: tokens | D30: Placeholder. gbrain chunking setting
A31: Synthesis answer length | B31: 600 | C31: tokens | D31: Placeholder (~450 words). Measure from real answers
A32: Entity-extraction prompt overhead | B32: 300 | C32: tokens | D32: Only used if the flag above = 1
A33: Entity-extraction output | B33: 400 | C33: tokens | D33: Only used if the flag above = 1
A34: Production projection (hypothetical — Spec requires 50–100 users)
A35: User count scenario A | B35: 50 | C35: users | D35: Spec Cost Transparency; Plan 10.4
A36: User count scenario B | B36: 75 | C36: users | D36: Plan 10.4
A37: User count scenario C | B37: 100 | C37: users | D37: Spec; Plan 10.4
A38: Queries per user per month | B38: 60 | C38: queries | D38: Team estimate ≈ 3 per workday (Plan 10.4 variable)
A39: Share of queries using Synthesis | B39: 0.4 | C39: % | D39: Team estimate; rest use Search
A40: Synthesis cache hit rate (prod) | B40: 0.05 | C40: % | D40: Spec 2: exact-match cache 'understood to have a low hit rate'
A41: New/edited docs per month — scenario A | B41: 25 | C41: docs | D41: Team estimate; scales with users (Spec: project growth with document volume)
...

Sheet Unit Costs
A1: Cost per Operation
A2: What one call of each kind costs with the current model choices.
A4: Operation | B4: Embedding tokens | C4: LLM input tokens | D4: LLM output tokens | E4: Cost per operation | F4: Cost tier | G4: How it's calculated
A5: Search query (embed question, pgvector lookup) | B5: =Assumptions!$B$27 -> 40 | C5: =0 -> 0 | D5: =0 -> 0 | E5: =B5/1000000*Assumptions!$B$51+C5/1000000*Assumptions!$B$49+D5/1000000*Assumptions!$B$50 -> 5.2e-06 | F5: Low (embedding) | G5: Question is embedded; ranking happens in Postgres for free
A6: Synthesis query — cache miss | B6: =Assumptions!$B$27 -> 40 | C6: =Assumptions!$B$28+Assumptions!$B$29*Assumptions!$B$30+Assumptions!$B$27 -> 4840 | D6: =Assumptions!$B$31 -> 600 | E6: =B6/1000000*Assumptions!$B$51+C6/1000000*Assumptions!$B$49+D6/1000000*Assumptions!$B$50 -> 0.0007892 | F6: Medium (synthesis) | G6: Embed question + send system prompt, retrieved chunks and question to the chat model
A7: Synthesis query — cache hit | B7: =0 -> 0 | C7: =0 -> 0 | D7: =0 -> 0 | E7: =B7/1000000*Assumptions!$B$51+C7/1000000*Assumptions!$B$49+D7/1000000*Assumptions!$B$50 -> 0 | F7: None (cache) | G7: Served from the app's exact-match cache; no OpenAI call
A8: Ingest one document | B8: =(Assumptions!$B$23/Assumptions!$B$12) -> 3000 | C8: =Assumptions!$B$25*((Assumptions!$B$23/Assumptions!$B$12)+Assumptions!$B$32) -> 0 | D8: =Assumptions!$B$25*Assumptions!$B$33 -> 0 | E8: =B8/1000000*Assumptions!$B$51+C8/1000000*Assumptions!$B$49+D8/1000000*Assumptions!$B$50 -> 0.00039 | F8: Low (embedding) | G8: Embed the whole doc; optional entity-extraction LLM call
A10: Cost per 1,000 synthesis queries (cache miss) | E10: =E6*1000 -> 0.7892
A11: Cost to ingest the full test corpus once | E11: =E8*Assumptions!$B$22 -> 0.0195
A12: Cost tiers per Spec (Token Economics): embedding = low-cost, answer synthesis = medium-cost.

Sheet Dev Phase Cost
A1: Development Phase API Cost (12-week capstone)
A2: Paid by the sponsor through the OpenAI keys he provided. This is the project's only real cost.
A4: Operation | B4: Volume (whole project) | C4: Cost each | D4: Total cost | E4: Volume basis
A5: Search — ad-hoc testing | B5: =Assumptions!$B$15*Assumptions!$B$16*Assumptions!$B$18 -> 2100 | C5: ='Unit Costs'!$E$5 -> 5.2e-06 | D5: =B5*C5 -> 0.01092 | E5: live weeks × members × searches/week
A6: Search — evaluation runs | B6: =Assumptions!$B$20*Assumptions!$B$21 -> 180 | C6: ='Unit Costs'!$E$5 -> 5.2e-06 | D6: =B6*C6 -> 0.000936 | E6: questions × runs (retrieval scoring, Plan §9.3)
A7: Synthesis — ad-hoc testing (cache miss) | B7: =Assumptions!$B$15*Assumptions!$B$16*Assumptions!$B$17*(1-Assumptions!$B$19) -> 1260 | C7: ='Unit Costs'!$E$6 -> 0.0007892 | D7: =B7*C7 -> 0.994392 | E7: live weeks × members × synth/week × (1 − hit rate)
A8: Synthesis — evaluation runs (cache miss) | B8: =Assumptions!$B$20*Assumptions!$B$21 -> 180 | C8: ='Unit Costs'!$E$6 -> 0.0007892 | D8: =B8*C8 -> 0.142056 | E8: questions × runs; KB changes between runs clear the cache
A9: Synthesis — cache hits | B9: =Assumptions!$B$15*Assumptions!$B$16*Assumptions!$B$17*Assumptions!$B$19 -> 140 | C9: ='Unit Costs'!$E$7 -> 0 | D9: =B9*C9 -> 0 | E9: Free: served from PostgreSQL cache
A10: Document ingestion | B10: =Assumptions!$B$22*Assumptions!$B$24 -> 300 | C10: ='Unit Costs'!$E$8 -> 0.00039 | D10: =B10*C10 -> 0.117 | E10: corpus size × full ingestions
A12: Subtotal (estimated API spend) | D12: =SUM(D5:D10) -> 1.265304
A13: Contingency buffer | B13: =Assumptions!$B$45 -> 0.25 | D13: =D12*B13 -> 0.316326
A14: Recommended dev-phase API budget | D14: =D12+D13 -> 1.58163
A15: Average per live week | D15: =D14/Assumptions!$B$15 -> 0.22594714
A16: Average per active month | D16: =D15*52/12 -> 0.97910429
A17: Monthly cost ceiling (token budget) | D17: =ROUNDUP(D16*Assumptions!$B$46,0) -> 2 | E17: Spec: 'define a projected monthly cost ceiling'

Sheet Production Projection
A1: Production Cost Projection (hypothetical — the project is not being deployed)
A2: Feeds the stretch cost dashboard's 50/75/100-user projection. Not a project expense.
A4: Monthly line item | B4: Scenario A | C4: Scenario B | D4: Scenario C
A5: Users | B5: =Assumptions!$B$35 -> 50 | C5: =Assumptions!$B$36 -> 75 | D5: =Assumptions!$B$37 -> 100
A6: Total queries / month | B6: =B5*Assumptions!$B$38 -> 3000 | C6: =C5*Assumptions!$B$38 -> 4500 | D6: =D5*Assumptions!$B$38 -> 6000
A7: Search queries | B7: =B6*(1-Assumptions!$B$39) -> 1800 | C7: =C6*(1-Assumptions!$B$39) -> 2700 | D7: =D6*(1-Assumptions!$B$39) -> 3600
A8: Synthesis queries — cache miss | B8: =B6*Assumptions!$B$39*(1-Assumptions!$B$40) -> 1140 | C8: =C6*Assumptions!$B$39*(1-Assumptions!$B$40) -> 1710 | D8: =D6*Assumptions!$B$39*(1-Assumptions!$B$40) -> 2280
A9: Synthesis queries — cache hit | B9: =B6*Assumptions!$B$39*Assumptions!$B$40 -> 60 | C9: =C6*Assumptions!$B$39*Assumptions!$B$40 -> 90 | D9: =D6*Assumptions!$B$39*Assumptions!$B$40 -> 120
A10: Docs ingested / month | B10: =Assumptions!$B$41 -> 25 | C10: =Assumptions!$B$42 -> 40 | D10: =Assumptions!$B$43 -> 50
A11: Search cost | B11: =B7*'Unit Costs'!$E$5 -> 0.00936 | C11: =C7*'Unit Costs'!$E$5 -> 0.01404 | D11: =D7*'Unit Costs'!$E$5 -> 0.01872
A12: Synthesis cost | B12: =B8*'Unit Costs'!$E$6+B9*'Unit Costs'!$E$7 -> 0.899688 | C12: =C8*'Unit Costs'!$E$6+C9*'Unit Costs'!$E$7 -> 1.349532 | D12: =D8*'Unit Costs'!$E$6+D9*'Unit Costs'!$E$7 -> 1.799376
A13: Ingestion cost | B13: =B10*'Unit Costs'!$E$8 -> 0.00975 | C13: =C10*'Unit Costs'!$E$8 -> 0.0156 | D13: =D10*'Unit Costs'!$E$8 -> 0.0195
A14: Monthly API cost | B14: =SUM(B11:B13) -> 0.918798 | C14: =SUM(C11:C13) -> 1.379172 | D14: =SUM(D11:D13) -> 1.837596
A15: With contingency buffer | B15: =B14*(1+Assumptions!$B$45) -> 1.1484975 | C15: =C14*(1+Assumptions!$B$45) -> 1.723965 | D15: =D14*(1+Assumptions!$B$45) -> 2.296995
A16: Annual (with buffer) | B16: =B15*12 -> 13.78197 | C16: =C15*12 -> 20.68758 | D16: =D15*12 -> 27.56394
A17: Cost per user / month | B17: =IF(B5=0,0,B15/B5) -> 0.02296995 | C17: =IF(C5=0,0,C15/C5) -> 0.0229862 | D17: =IF(D5=0,0,D15/D5) -> 0.02296995
A18: Saved by cache / month | B18: =B9*('Unit Costs'!$E$6-'Unit Costs'!$E$7) -> 0.047352 | C18: =C9*('Unit Costs'!$E$6-'Unit Costs'!$E$7) -> 0.071028 | D18: =D9*('Unit Costs'!$E$6-'Unit Costs'!$E$7) -> 0.094704
A19: Monthly cost ceiling | B19: =ROUNDUP(B15*Assumptions!$B$46,0) -> 3 | C19: =ROUNDUP(C15*Assumptions!$B$46,0) -> 4 | D19: =ROUNDUP(D15*Assumptions!$B$46,0) -> 5
A21: How cost grows with document volume (one-time cost to ingest a whole corpus)
A22: Corpus size (docs) | B22: Ingestion cost
A23: 50 | B23: =A23*'Unit Costs'!$E$8 -> 0.0195
A24: 500 | B24: =A24*'Unit Costs'!$E$8 -> 0.195
A25: 5000 | B25: =A25*'Unit Costs'!$E$8 -> 1.95
A26: 50000 | B26: =A26*'Unit Costs'!$E$8 -> 19.5
A27: Ingestion is embedding-only (low tier), so even large corpora stay cheap; Synthesis volume drives cost.

Sheet Model Comparison
A1: What if we used a different chat model?
A2: Same usage assumptions, only the synthesis model changes. Embedding and cache-hit costs held constant.
A4: Chat model | B4: Cost per synthesis (miss) | C4: Dev-phase total (with buffer) | D4: Prod monthly @ Scenario C (with buffer)
A5: ='Price Reference'!A4 -> gpt-6-astra | B5: =('Unit Costs'!$B$6/1000000*Assumptions!$B$51+'Unit Costs'!$C$6/1000000*'Price Reference'!$C$4+'Unit Costs'!$D$6/1000000*'Price Reference'!$E$4) -> 0.0784052 | C5: =(('Dev Phase Cost'!$B$5+'Dev Phase Cost'!$B$6)*'Unit Costs'!$E$5+('Dev Phase Cost'!$B$7+'Dev Phase Cost'!$B$8)*B5+'Dev Phase Cost'!$B$10*('Unit Costs'!$B$8/1000000*Assumptions!$B$51+'Unit Costs'!$C$8/1000000*'Price Reference'!$C$4+'Unit Costs'!$D$8/1000000*'Price Reference'!$E$4))*(1+Assumptions!$B$45) -> 141.29043 | D5: =('Production Projection'!$D$7*'Unit Costs'!$E$5+'Production Projection'!$D$8*B5+'Production Projection'!$D$10*('Unit Costs'!$B$8/1000000*Assumptions!$B$51+'Unit Costs'!$C$8/1000000*'Price Reference'!$C$4+'Unit Costs'!$D$8/1000000*'Price Reference'!$E$4))*(1+Assumptions!$B$45) -> 223.5026
A6: ='Price Reference'!A5 -> gpt-6-sol | B6: =('Unit Costs'!$B$6/1000000*Assumptions!$B$51+'Unit Costs'!$C$6/1000000*'Price Reference'!$C$5+'Unit Costs'!$D$6/1000000*'Price Reference'!$E$5) -> 0.0156852 | C6: =(('Dev Phase Cost'!$B$5+'Dev Phase Cost'!$B$6)*'Unit Costs'!$E$5+('Dev Phase Cost'!$B$7+'Dev Phase Cost'!$B$8)*B6+'Dev Phase Cost'!$B$10*('Unit Costs'!$B$8/1000000*Assumptions!$B$51+'Unit Costs'!$C$8/1000000*'Price Reference'!$C$5+'Unit Costs'!$D$8/1000000*'Price Reference'!$E$5))*(1+Assumptions!$B$45) -> 28.39443 | D6: =('Production Projection'!$D$7*'Unit Costs'!$E$5+'Production Projection'!$D$8*B6+'Production Projection'!$D$10*('Unit Costs'!$B$8/1000000*Assumptions!$B$51+'Unit Costs'!$C$8/1000000*'Price Reference'!$C$5+'Unit Costs'!$D$8/1000000*'Price Reference'!$E$5))*(1+Assumptions!$B$45) -> 44.750595
A7: ='Price Reference'!A6 -> gpt-6-luna | B7: =('Unit Costs'!$B$6/1000000*Assumptions!$B$51+'Unit Costs'!$C$6/1000000*'Price Reference'!$C$6+'Unit Costs'!$D$6/1000000*'Price Reference'!$E$6) -> 0.0007892 | C7: =(('Dev Phase Cost'!$B$5+'Dev Phase Cost'!$B$6)*'Unit Costs'!$E$5+('Dev Phase Cost'!$B$7+'Dev Phase Cost'!$B$8)*B7+'Dev Phase Cost'!$B$10*('Unit Costs'!$B$8/1000000*Assumptions!$B$51+'Unit Costs'!$C$8/1000000*'Price Reference'!$C$6+'Unit Costs'!$D$8/1000000*'Price Reference'!$E$6))*(1+Assumptions!$B$45) -> 1.58163 | D7: =('Production Projection'!$D$7*'Unit Costs'!$E$5+'Production Projection'!$D$8*B7+'Production Projection'!$D$10*('Unit Costs'!$B$8/1000000*Assumptions!$B$51+'Unit Costs'!$C$8/1000000*'Price Reference'!$C$6+'Unit Costs'!$D$8/1000000*'Price Reference'!$E$6))*(1+Assumptions!$B$45) -> 2.296995

Sheet Other Costs
A1: All Project Costs
A2: Every tool the project uses, including the free ones, so reviewers can see nothing was missed.
A4: Item | B4: Category | C4: Paid by | D4: Project cost | E4: Why
A5: OpenAI API usage (dev phase, with buffer) | B5: API (usage-based) | C5: Sponsor | D5: ='Dev Phase Cost'!D14 -> 1.58163 | E5: Sponsor-provided OpenAI keys; see Dev Phase Cost tab
A6: React frontend | B6: Software | C6: Free | D6: 0 | E6: Open source
A7: Spring Boot backend | B7: Software | C7: Free | D7: 0 | E7: Open source
A8: PostgreSQL + pgvector | B8: Software / database | C8: Free | D8: 0 | E8: Open source, runs locally in Docker
A9: gbrain | B9: Software | C9: Free | D9: 0 | E9: Open source; its OpenAI usage is counted in the API line
A10: Docker / Docker Compose | B10: Tooling | C10: Free | D10: 0 | E10: Free for education/personal use; sponsor provides compose config
A11: Hosting / cloud infrastructure | B11: Infrastructure | C11: Free | D11: 0 | E11: Optional shared demo env (Plan 2.3) not planned; local Docker Compose only
A12: Source control (GitHub) | B12: Tooling | C12: Free | D12: 0 | E12: Free tier
A13: Diagramming (draw.io) & docs (Google Drive) | B13: Tooling | C13: Free | D13: 0 | E13: Free
A14: Claude Code (AI dev tool) | B14: Tooling | C14: Students | D14: 0 | E14: Listed in Spec as a dev tool. Each student's own subscription; not a project expense. Confirm
A15: Developer hardware | B15: Hardware | C15: Students | D15: 0 | E15: Team members' existing laptops
A16: Student labor | B16: Labor | C16: N/A | D16: 0 | E16: Excluded: unpaid academic capstone
A18: Total project cost | D18: =SUM(D5:D16) -> 1.58163
A19: Paid by sponsor | D19: =SUMIF(C5:C16,"Sponsor",D5:D16) -> 1.58163
A20: Team out-of-pocket | D20: =SUMIF(C5:C16,"Team",D5:D16) -> 0

Sheet Price Reference
A1: OpenAI API Price Reference (USD per 1M tokens, Standard tier, short context)
A3: Model | B3: Type | C3: Input $/1M | D3: Cached input $/1M | E3: Output $/1M | F3: Source / note
A4: gpt-6-astra | B4: Chat / synthesis | C4: 10 | D4: 1 | E4: 50 | F4: OpenAI pricing page, checked 2026-09-26: developers.openai.com/api/docs/pricing
A5: gpt-6-sol | B5: Chat / synthesis | C5: 2 | D5: 0.2 | E5: 10 | F5: OpenAI pricing page, checked 2026-09-26
A6: gpt-6-luna | B6: Chat / synthesis | C6: 0.1 | D6: 0.01 | E6: 0.5 | F6: OpenAI pricing page, checked 2026-09-26
A7: text-embedding-3-large | B7: Embedding | C7: 0.13 | E7: 0 | F7: gbrain's default OpenAI embedding model (1536 dims). $0.13/1M per gbrain docs
A8: text-embedding-3-small | B8: Embedding | C8: 0.02 | E8: 0 | F8: Cheaper alternative gbrain supports; confirm on OpenAI pricing page
A11: Batch API halves prices; long-context (>272K input tokens) costs more. Neither applies at KnowledgeBridge's request sizes.
